{
    DataVersion: 3465,
    size: [16, 4, 16],
    data: [
        {pos: [2, 0, 6], state: "ae2:drive{facing:north,spin:0}", nbt: {id: "ae2:drive", inv: {item0: {}, item1: {}, item2: {}, item3: {}, item4: {}, item5: {}, item6: {}, item7: {}, item8: {}, item9: {}}, priority: 0, proxy: {p: 0}, visual: {online: 1b}}},
        {pos: [3, 0, 6], state: "ae2:drive{facing:north,spin:0}", nbt: {id: "ae2:drive", inv: {item0: {}, item1: {}, item2: {}, item3: {}, item4: {}, item5: {}, item6: {}, item7: {}, item8: {}, item9: {}}, priority: 0, proxy: {p: 0}, visual: {online: 1b}}},
        {pos: [5, 0, 6], state: "ae2:drive{facing:north,spin:0}", nbt: {id: "ae2:drive", inv: {item0: {}, item1: {}, item2: {}, item3: {}, item4: {}, item5: {}, item6: {}, item7: {}, item8: {}, item9: {}}, priority: 0, proxy: {p: 0}, visual: {online: 1b}}},
        {pos: [6, 0, 6], state: "ae2:drive{facing:north,spin:0}", nbt: {id: "ae2:drive", inv: {item0: {}, item1: {}, item2: {}, item3: {}, item4: {}, item5: {}, item6: {}, item7: {}, item8: {}, item9: {}}, priority: 0, proxy: {p: 0}, visual: {online: 1b}}},
        {pos: [8, 0, 6], state: "ae2:cell_workbench{facing:north,spin:0}", nbt: {copy_mode: "CLEAR_ON_REMOVE", id: "ae2:cell_workbench", visual: {}}},
        {pos: [13, 0, 13], state: "minecraft:stone_brick_wall{east:none,north:none,south:none,up:true,waterlogged:false,west:none}"},
        {pos: [13, 0, 15], state: "minecraft:stone_brick_wall{east:none,north:none,south:none,up:true,waterlogged:false,west:none}"},
        {pos: [14, 0, 9], state: "ae2:condenser", nbt: {condenser_output: "TRASH", id: "ae2:condenser", inv: {item0: {}, item1: {}, item2: {}}, storedPower: 0.0d, visual: {}}},
        {pos: [14, 0, 11], state: "ae2:drive{facing:east,spin:0}", nbt: {id: "ae2:drive", inv: {item0: {Count: 1b, id: "ae2:item_storage_cell_16k", tag: {amts: [L; 2L, 65L], ic: 67L, keys: [{"#c": "ae2:i", id: "minecraft:arrow"}, {"#c": "ae2:i", id: "minecraft:bone"}], list: [{"#": 0L, "#c": "ae2:i", id: "minecraft:bone"}, {"#": 0L, "#c": "ae2:i", id: "minecraft:rotten_flesh"}, {"#": 0L, "#c": "ae2:i", id: "minecraft:carrot"}, {"#": 0L, "#c": "ae2:i", id: "minecraft:iron_ingot"}, {"#": 0L, "#c": "ae2:i", id: "minecraft:arrow"}], upgrades: [{Count: 1b, Slot: 0, id: "ae2:equal_distribution_card"}, {Count: 1b, Slot: 1, id: "ae2:void_card"}]}}, item1: {Count: 1b, id: "ae2:item_storage_cell_16k", tag: {amts: [L; 2L], ic: 2L, keys: [{"#c": "ae2:i", id: "minecraft:arrow"}], list: [{"#": 0L, "#c": "ae2:i", id: "minecraft:bone"}, {"#": 0L, "#c": "ae2:i", id: "minecraft:rotten_flesh"}, {"#": 0L, "#c": "ae2:i", id: "minecraft:carrot"}, {"#": 0L, "#c": "ae2:i", id: "minecraft:iron_ingot"}, {"#": 0L, "#c": "ae2:i", id: "minecraft:arrow"}], upgrades: [{Count: 1b, Slot: 0, id: "ae2:equal_distribution_card"}, {Count: 1b, Slot: 1, id: "ae2:void_card"}]}}, item2: {}, item3: {}, item4: {}, item5: {}, item6: {}, item7: {}, item8: {}, item9: {}}, priority: 0, proxy: {p: 0}, visual: {cell0: {id: "ae2:item_storage_cell_16k", state: "not_empty"}, cell1: {id: "ae2:item_storage_cell_16k", state: "not_empty"}, online: 1b}}},
        {pos: [14, 0, 12], state: "ae2:cable_bus{light_level:0,waterlogged:false}", nbt: {cable: {gn: {p: 0}, id: "ae2:orange_smart_cable", visual: {channelsNorth: 5, channelsSouth: 5, connections: ["north", "south"], missingChannel: 0b, powered: 1b}}, hasRedstone: 2, id: "ae2:cable_bus", visual: {}}},
        {pos: [14, 0, 13], state: "ae2:cable_bus{light_level:0,waterlogged:false}", nbt: {cable: {gn: {p: 0}, id: "ae2:orange_smart_cable", visual: {channelsNorth: 5, connections: ["north"], missingChannel: 0b, powered: 1b}}, hasRedstone: 2, id: "ae2:cable_bus", up: {fuzzy_mode: "IGNORE_ALL", gn: {p: 0}, id: "ae2:cable_interface", priority: 0, visual: {missingChannel: 0b, powered: 1b}}, visual: {}}},
        {pos: [15, 0, 13], state: "minecraft:stone_brick_wall{east:none,north:none,south:none,up:true,waterlogged:false,west:none}"},
        {pos: [15, 0, 15], state: "minecraft:stone_brick_wall{east:none,north:none,south:none,up:true,waterlogged:false,west:none}"},
        {pos: [2, 1, 6], state: "ae2:drive{facing:north,spin:0}", nbt: {id: "ae2:drive", inv: {item0: {}, item1: {}, item2: {}, item3: {}, item4: {}, item5: {}, item6: {}, item7: {}, item8: {}, item9: {}}, priority: 0, proxy: {p: 0}, visual: {online: 1b}}},
        {pos: [3, 1, 6], state: "ae2:drive{facing:north,spin:0}", nbt: {id: "ae2:drive", inv: {item0: {}, item1: {}, item2: {}, item3: {}, item4: {}, item5: {}, item6: {}, item7: {}, item8: {}, item9: {}}, priority: 0, proxy: {p: 0}, visual: {online: 1b}}},
        {pos: [5, 1, 6], state: "ae2:drive{facing:north,spin:0}", nbt: {id: "ae2:drive", inv: {item0: {}, item1: {}, item2: {}, item3: {}, item4: {}, item5: {}, item6: {}, item7: {}, item8: {}, item9: {}}, priority: 0, proxy: {p: 0}, visual: {online: 1b}}},
        {pos: [6, 1, 6], state: "ae2:drive{facing:north,spin:0}", nbt: {id: "ae2:drive", inv: {item0: {Count: 1b, id: "ae2:item_storage_cell_256k", tag: {amts: [L; 1L], ic: 1L, keys: [{"#c": "ae2:i", id: "minecraft:iron_ingot"}], list: [{"#": 0L, "#c": "ae2:i", id: "minecraft:iron_ingot"}]}}, item1: {}, item2: {}, item3: {}, item4: {}, item5: {}, item6: {}, item7: {}, item8: {}, item9: {}}, priority: 0, proxy: {p: 0}, visual: {cell0: {id: "ae2:item_storage_cell_256k", state: "not_empty"}, online: 1b}}},
        {pos: [8, 1, 6], state: "ae2:cable_bus{light_level:9,waterlogged:false}", nbt: {cable: {gn: {p: 0}, id: "ae2:blue_smart_cable", visual: {channelsUp: 1, connections: ["up"], missingChannel: 0b, powered: 1b}}, hasRedstone: 2, id: "ae2:cable_bus", north: {filter_type: "ALL", gn: {p: 0}, id: "ae2:crafting_terminal", sort_by: "NAME", sort_direction: "ASCENDING", spin: 0b, view_mode: "ALL", visual: {missingChannel: 0b, powered: 1b}}, visual: {}}},
        {pos: [13, 1, 10], state: "ae2:cable_bus{light_level:0,waterlogged:false}", nbt: {cable: {gn: {p: 0}, id: "ae2:orange_smart_cable", visual: {channelsEast: 5, connections: ["east"], missingChannel: 0b, powered: 1b}}, hasRedstone: 2, id: "ae2:cable_bus", up: {gn: {p: 0}, id: "ae2:quartz_fiber", outer: {p: 0}, visual: {missingChannel: 0b, powered: 1b}}, visual: {}}},
        {pos: [13, 1, 13], state: "minecraft:stone_bricks"},
        {pos: [13, 1, 14], state: "minecraft:stone_bricks"},
        {pos: [13, 1, 15], state: "minecraft:stone_bricks"},
        {pos: [14, 1, 9], state: "ae2:cable_bus{light_level:0,waterlogged:false}", nbt: {cable: {gn: {p: 0}, id: "ae2:orange_smart_cable", visual: {channelsSouth: 5, connections: ["south"], missingChannel: 0b, powered: 1b}}, down: {access: "READ_WRITE", filter_on_extract: "YES", fuzzy_mode: "IGNORE_ALL", gn: {p: 0}, id: "ae2:storage_bus", priority: -1, storage_filter: "EXTRACTABLE_ONLY", visual: {missingChannel: 0b, powered: 1b}}, hasRedstone: 2, id: "ae2:cable_bus", visual: {}}},
        {pos: [14, 1, 10], state: "ae2:interface", nbt: {fuzzy_mode: "IGNORE_ALL", id: "ae2:interface", priority: 0, proxy: {p: 0}, visual: {}}},
        {pos: [14, 1, 11], state: "ae2:cable_bus{light_level:9,waterlogged:false}", nbt: {cable: {gn: {p: 0}, id: "ae2:orange_smart_cable", visual: {channelsDown: 5, channelsNorth: 5, connections: ["down", "north"], missingChannel: 0b, powered: 1b}}, east: {filter_type: "ALL", gn: {p: 0}, id: "ae2:crafting_terminal", sort_by: "NAME", sort_direction: "ASCENDING", spin: 0b, view_mode: "ALL", visual: {missingChannel: 0b, powered: 1b}}, hasRedstone: 2, id: "ae2:cable_bus", visual: {}}},
        {pos: [14, 1, 13], state: "minecraft:hopper{enabled:true,facing:down}", nbt: {Items: [], TransferCooldown: 0, id: "minecraft:hopper"}},
        {pos: [14, 1, 14], state: "minecraft:stone_bricks"},
        {pos: [14, 1, 15], state: "minecraft:stone_bricks"},
        {pos: [15, 1, 13], state: "minecraft:stone_bricks"},
        {pos: [15, 1, 14], state: "minecraft:stone_bricks"},
        {pos: [15, 1, 15], state: "minecraft:stone_bricks"},
        {pos: [3, 2, 6], state: "ae2:cable_bus{light_level:0,waterlogged:false}", nbt: {cable: {gn: {p: 0}, id: "ae2:blue_smart_cable", visual: {channelsDown: 4, channelsEast: 4, connections: ["down", "east"], missingChannel: 0b, powered: 1b}}, hasRedstone: 2, id: "ae2:cable_bus", visual: {}}},
        {pos: [4, 2, 6], state: "ae2:cable_bus{light_level:0,waterlogged:false}", nbt: {cable: {gn: {p: 0}, id: "ae2:blue_smart_cable", visual: {channelsEast: 4, channelsWest: 4, connections: ["west", "east"], missingChannel: 0b, powered: 1b}}, hasRedstone: 2, id: "ae2:cable_bus", visual: {}}},
        {pos: [5, 2, 6], state: "ae2:cable_bus{light_level:0,waterlogged:false}", nbt: {cable: {gn: {p: 0}, id: "ae2:blue_smart_cable", visual: {channelsEast: 4, channelsWest: 4, connections: ["west", "east"], missingChannel: 0b, powered: 1b}}, down: {id: "ae2:cable_anchor", visual: {}}, hasRedstone: 2, id: "ae2:cable_bus", visual: {}}},
        {pos: [6, 2, 6], state: "ae2:cable_bus{light_level:0,waterlogged:false}", nbt: {cable: {gn: {p: 0}, id: "ae2:blue_smart_dense_cable", visual: {channelsDown: 4, channelsEast: 8, channelsWest: 4, connections: ["down", "west", "east"], missingChannel: 0b, powered: 1b}}, hasRedstone: 2, id: "ae2:cable_bus", visual: {}}},
        {pos: [7, 2, 6], state: "ae2:cable_bus{light_level:0,waterlogged:false}", nbt: {cable: {gn: {p: 0}, id: "ae2:blue_smart_dense_cable", visual: {channelsEast: 8, channelsWest: 8, connections: ["west", "east"], missingChannel: 0b, powered: 1b}}, hasRedstone: 2, id: "ae2:cable_bus", visual: {}}},
        {pos: [8, 2, 6], state: "ae2:controller{state:online,type:block}", nbt: {id: "ae2:controller", internalCurrentPower: 0.0d, proxy: {p: 0}, visual: {}}},
        {pos: [8, 2, 10], state: "ae2:cable_bus{light_level:0,waterlogged:false}", nbt: {cable: {gn: {p: 0}, id: "ae2:blue_smart_cable", visual: {channelsEast: 0, connections: ["east"], missingChannel: 0b, powered: 1b}}, hasRedstone: 2, id: "ae2:cable_bus", visual: {}}},
        {pos: [9, 2, 6], state: "ae2:cable_bus{light_level:0,waterlogged:false}", nbt: {cable: {gn: {p: 0}, id: "ae2:blue_smart_dense_cable", visual: {channelsEast: 1, channelsWest: 1, connections: ["west", "east"], missingChannel: 0b, powered: 1b}}, hasRedstone: 2, id: "ae2:cable_bus", visual: {}}},
        {pos: [9, 2, 10], state: "ae2:cable_bus{light_level:0,waterlogged:false}", nbt: {cable: {gn: {p: 0}, id: "ae2:blue_smart_cable", visual: {channelsEast: 0, channelsWest: 0, connections: ["west", "east"], missingChannel: 0b, powered: 1b}}, hasRedstone: 2, id: "ae2:cable_bus", visual: {}}},
        {pos: [10, 2, 6], state: "ae2:cable_bus{light_level:0,waterlogged:false}", nbt: {cable: {gn: {p: 0}, id: "ae2:blue_smart_dense_cable", visual: {channelsEast: 1, channelsWest: 1, connections: ["west", "east"], missingChannel: 0b, powered: 1b}}, hasRedstone: 2, id: "ae2:cable_bus", visual: {}}},
        {pos: [10, 2, 10], state: "ae2:cable_bus{light_level:0,waterlogged:false}", nbt: {cable: {gn: {p: 0}, id: "ae2:blue_smart_cable", visual: {channelsEast: 0, channelsWest: 0, connections: ["west", "east"], missingChannel: 0b, powered: 1b}}, hasRedstone: 2, id: "ae2:cable_bus", visual: {}}},
        {pos: [11, 2, 6], state: "ae2:cable_bus{light_level:0,waterlogged:false}", nbt: {cable: {gn: {p: 0}, id: "ae2:blue_smart_dense_cable", visual: {channelsSouth: 1, channelsWest: 1, connections: ["south", "west"], missingChannel: 0b, powered: 1b}}, hasRedstone: 2, id: "ae2:cable_bus", visual: {}}},
        {pos: [11, 2, 7], state: "ae2:cable_bus{light_level:0,waterlogged:false}", nbt: {cable: {gn: {p: 0}, id: "ae2:blue_smart_dense_cable", visual: {channelsNorth: 1, channelsSouth: 1, connections: ["north", "south"], missingChannel: 0b, powered: 1b}}, hasRedstone: 2, id: "ae2:cable_bus", visual: {}}},
        {pos: [11, 2, 8], state: "ae2:cable_bus{light_level:0,waterlogged:false}", nbt: {cable: {gn: {p: 0}, id: "ae2:blue_smart_dense_cable", visual: {channelsNorth: 1, channelsSouth: 1, connections: ["north", "south"], missingChannel: 0b, powered: 1b}}, hasRedstone: 2, id: "ae2:cable_bus", visual: {}}},
        {pos: [11, 2, 9], state: "ae2:cable_bus{light_level:0,waterlogged:false}", nbt: {cable: {gn: {p: 0}, id: "ae2:blue_smart_dense_cable", visual: {channelsNorth: 1, channelsSouth: 1, connections: ["north", "south"], missingChannel: 0b, powered: 1b}}, hasRedstone: 2, id: "ae2:cable_bus", visual: {}}},
        {pos: [11, 2, 10], state: "ae2:cable_bus{light_level:0,waterlogged:false}", nbt: {cable: {gn: {p: 0}, id: "ae2:blue_smart_dense_cable", visual: {channelsEast: 1, channelsNorth: 1, channelsWest: 0, connections: ["north", "west", "east"], missingChannel: 0b, powered: 1b}}, hasRedstone: 2, id: "ae2:cable_bus", visual: {}}},
        {pos: [12, 2, 10], state: "ae2:cable_bus{light_level:0,waterlogged:false}", nbt: {cable: {gn: {p: 0}, id: "ae2:blue_smart_cable", visual: {channelsEast: 1, channelsWest: 1, connections: ["west", "east"], missingChannel: 0b, powered: 1b}}, hasRedstone: 2, id: "ae2:cable_bus", visual: {}}},
        {pos: [13, 2, 10], state: "ae2:cable_bus{light_level:0,waterlogged:false}", nbt: {cable: {gn: {p: 0}, id: "ae2:blue_smart_cable", visual: {channelsDown: 0, channelsEast: 1, channelsWest: 1, connections: ["down", "west", "east"], missingChannel: 0b, powered: 1b}}, hasRedstone: 2, id: "ae2:cable_bus", visual: {}}},
        {pos: [13, 2, 13], state: "minecraft:mossy_cobblestone"},
        {pos: [13, 2, 14], state: "minecraft:tinted_glass"},
        {pos: [13, 2, 15], state: "minecraft:mossy_cobblestone"},
        {pos: [14, 2, 10], state: "ae2:cable_bus{light_level:0,waterlogged:false}", nbt: {cable: {gn: {p: 0}, id: "ae2:blue_smart_cable", visual: {channelsWest: 1, connections: ["west"], missingChannel: 0b, powered: 1b}}, down: {access: "READ_WRITE", config: [{"#": 0L, "#c": "ae2:i", id: "minecraft:arrow"}, {"#": 0L, "#c": "ae2:i", id: "minecraft:rotten_flesh"}, {"#": 0L, "#c": "ae2:i", id: "minecraft:bone"}], filter_on_extract: "YES", fuzzy_mode: "IGNORE_ALL", gn: {p: 0}, id: "ae2:storage_bus", priority: 0, storage_filter: "EXTRACTABLE_ONLY", visual: {missingChannel: 0b, powered: 1b}}, hasRedstone: 2, id: "ae2:cable_bus", visual: {}}},
        {pos: [14, 2, 13], state: "minecraft:tinted_glass"},
        {pos: [14, 2, 15], state: "minecraft:tinted_glass"},
        {pos: [15, 2, 13], state: "minecraft:mossy_cobblestone"},
        {pos: [15, 2, 14], state: "minecraft:tinted_glass"},
        {pos: [15, 2, 15], state: "minecraft:mossy_cobblestone"},
        {pos: [8, 3, 6], state: "ae2:creative_energy_cell", nbt: {id: "ae2:creative_energy_cell", proxy: {p: 0}, visual: {}}},
        {pos: [13, 3, 13], state: "minecraft:stone_bricks"},
        {pos: [13, 3, 14], state: "minecraft:stone_bricks"},
        {pos: [13, 3, 15], state: "minecraft:stone_bricks"},
        {pos: [14, 3, 13], state: "minecraft:stone_bricks"},
        {pos: [14, 3, 14], state: "minecraft:tinted_glass"},
        {pos: [14, 3, 15], state: "minecraft:stone_bricks"},
        {pos: [15, 3, 13], state: "minecraft:stone_bricks"},
        {pos: [15, 3, 14], state: "minecraft:stone_bricks"},
        {pos: [15, 3, 15], state: "minecraft:stone_bricks"}
    ],
    entities: [],
    palette: [
        "minecraft:stone_bricks",
        "minecraft:mossy_cobblestone",
        "minecraft:tinted_glass",
        "minecraft:stone_brick_wall{east:none,north:none,south:none,up:true,waterlogged:false,west:none}",
        "ae2:drive{facing:north,spin:0}",
        "ae2:cell_workbench{facing:north,spin:0}",
        "ae2:condenser",
        "ae2:drive{facing:east,spin:0}",
        "ae2:cable_bus{light_level:0,waterlogged:false}",
        "ae2:cable_bus{light_level:9,waterlogged:false}",
        "ae2:interface",
        "minecraft:hopper{enabled:true,facing:down}",
        "ae2:controller{state:online,type:block}",
        "ae2:creative_energy_cell"
    ]
}