{
    DataVersion: 3700,
    size: [16, 4, 16],
    data: [
        {pos: [7, 0, 13], state: "minecraft:dirt"},
        {pos: [7, 0, 14], state: "minecraft:farmland{moisture:7}"},
        {pos: [7, 0, 15], state: "minecraft:dirt"},
        {pos: [8, 0, 13], state: "minecraft:farmland{moisture:7}"},
        {pos: [8, 0, 14], state: "minecraft:smooth_stone_slab{type:bottom,waterlogged:true}"},
        {pos: [8, 0, 15], state: "minecraft:farmland{moisture:7}"},
        {pos: [9, 0, 13], state: "minecraft:dirt"},
        {pos: [9, 0, 14], state: "minecraft:farmland{moisture:7}"},
        {pos: [9, 0, 15], state: "minecraft:dirt"},
        {pos: [11, 0, 1], state: "minecraft:barrel{facing:east,open:false}", nbt: {Items: [{Count: 64b, Slot: 0b, id: "minecraft:coal"}, {Count: 64b, Slot: 1b, id: "minecraft:coal"}, {Count: 1b, Slot: 2b, id: "minecraft:coal"}], id: "minecraft:barrel"}},
        {pos: [11, 0, 3], state: "ae2:drive{facing:east,spin:0}", nbt: {id: "ae2:drive", inv: {item0: {Count: 1b, id: "ae2:item_storage_cell_256k", tag: {amts: [L; 2179L, 2881L], ic: 5060L, keys: [{"#t": "ae2:i", id: "minecraft:iron_ingot"}, {"#t": "ae2:i", id: "minecraft:cobblestone"}], list: [{"#": 0L, "#t": "ae2:i", id: "minecraft:iron_ingot"}, {"#": 0L, "#t": "ae2:i", id: "minecraft:cobblestone"}], upgrades: [{Count: 1b, Slot: 0, id: "ae2:equal_distribution_card"}]}}, item1: {}, item2: {}, item3: {}, item4: {}, item5: {}, item6: {}, item7: {}, item8: {}, item9: {}}, priority: 1, proxy: {p: 2}, visual: {cell0: {id: "ae2:item_storage_cell_256k", state: "not_empty"}, online: 1b}}},
        {pos: [11, 0, 5], state: "ae2:drive{facing:east,spin:0}", nbt: {id: "ae2:drive", inv: {item0: {Count: 1b, id: "ae2:item_storage_cell_16k", tag: {amts: [L; 1L, 1L, 3L, 2L, 2L, 1L, 3L, 64L, 2L, 2L, 1L, 1L, 1L, 1L, 3L, 2L, 1L, 2L, 1L, 2L, 1L, 3L, 1L, 1L, 64L, 1L, 64L, 5L, 1L, 2L, 64L, 128L, 3L, 4L, 2L, 5L, 2L, 64L, 1L, 2L, 7L, 1L, 3L, 34L, 3L, 1L, 2L, 257L, 1L, 1L, 1L, 2L, 1L, 3L, 1L, 1L, 9L, 1L, 1L, 2L, 25L, 7L, 3L], ic: 881L, keys: [{"#t": "ae2:i", id: "minecraft:light_blue_wool"}, {"#t": "ae2:i", id: "minecraft:water_bucket"}, {"#t": "ae2:i", id: "minecraft:white_bed"}, {"#t": "ae2:i", id: "minecraft:observer"}, {"#t": "ae2:i", id: "minecraft:purple_wool"}, {"#t": "ae2:i", id: "ae2:blue_smart_dense_cable"}, {"#t": "ae2:i", id: "minecraft:pumpkin"}, {"#t": "ae2:i", id: "minecraft:cobblestone_slab"}, {"#t": "ae2:i", id: "minecraft:dispenser"}, {"#t": "ae2:i", id: "minecraft:gray_concrete"}, {"#t": "ae2:i", id: "minecraft:end_rod"}, {"#t": "ae2:i", id: "minecraft:furnace"}, {"#t": "ae2:i", id: "minecraft:white_concrete"}, {"#t": "ae2:i", id: "ae2:red_smart_cable"}, {"#t": "ae2:i", id: "minecraft:redstone_torch"}, {"#t": "ae2:i", id: "minecraft:light_gray_wool"}, {"#t": "ae2:i", id: "minecraft:orange_tulip"}, {"#t": "ae2:i", id: "minecraft:red_wool"}, {"#t": "ae2:i", id: "minecraft:blue_wool"}, {"#t": "ae2:i", id: "minecraft:oak_sapling"}, {"#t": "ae2:i", id: "minecraft:bucket"}, {"#t": "ae2:i", id: "minecraft:chest"}, {"#t": "ae2:i", id: "minecraft:azure_bluet"}, {"#t": "ae2:i", id: "minecraft:crafting_table"}, {"#t": "ae2:i", id: "minecraft:mossy_stone_bricks"}, {"#t": "ae2:i", id: "ae2:cable_interface"}, {"#t": "ae2:i", id: "minecraft:cobblestone_stairs"}, {"#t": "ae2:i", id: "ae2:inverter_card"}, {"#t": "ae2:i", id: "ae2:orange_smart_cable"}, {"#t": "ae2:i", id: "minecraft:dropper"}, {"#t": "ae2:i", id: "minecraft:diorite"}, {"#t": "ae2:i", id: "minecraft:oak_log"}, {"#t": "ae2:i", id: "minecraft:sticky_piston"}, {"#t": "ae2:i", id: "minecraft:redstone_lamp"}, {"#t": "ae2:i", id: "minecraft:blast_furnace"}, {"#t": "ae2:i", id: "minecraft:spruce_sapling"}, {"#t": "ae2:i", id: "minecraft:pink_terracotta"}, {"#t": "ae2:i", id: "minecraft:quartz_block"}, {"#t": "ae2:i", id: "ae2:formation_plane"}, {"#t": "ae2:i", id: "ae2:quartz_fiber"}, {"#t": "ae2:i", id: "minecraft:torch"}, {"#t": "ae2:i", id: "minecraft:allium"}, {"#t": "ae2:i", id: "minecraft:composter"}, {"#t": "ae2:i", id: "ae2:speed_card"}, {"#t": "ae2:i", id: "minecraft:sea_lantern"}, {"#t": "ae2:i", id: "minecraft:red_stained_glass"}, {"#t": "ae2:i", id: "minecraft:black_wool"}, {"#t": "ae2:i", id: "minecraft:stone"}, {"#t": "ae2:i", id: "minecraft:light_gray_concrete"}, {"#t": "ae2:i", id: "minecraft:pink_tulip"}, {"#t": "ae2:i", id: "ae2:cable_anchor"}, {"#t": "ae2:i", id: "minecraft:brown_stained_glass"}, {"#t": "ae2:i", id: "minecraft:sculk_sensor"}, {"#t": "ae2:i", id: "ae2:storage_bus"}, {"#t": "ae2:i", id: "minecraft:jungle_sapling"}, {"#t": "ae2:i", id: "ae2:growth_accelerator"}, {"#t": "ae2:i", id: "minecraft:redstone"}, {"#t": "ae2:i", id: "minecraft:repeater"}, {"#t": "ae2:i", id: "minecraft:poppy"}, {"#t": "ae2:i", id: "minecraft:dandelion"}, {"#t": "ae2:i", id: "minecraft:oak_planks"}, {"#t": "ae2:i", id: "minecraft:piston"}, {"#t": "ae2:i", id: "minecraft:cornflower"}]}}, item1: {Count: 1b, id: "ae2:item_storage_cell_16k", tag: {amts: [L; 2L, 3L, 1L, 2L, 1L, 2L, 1L, 1L, 4L, 1L, 1L, 4L, 64L, 2L, 1L, 1L, 4L, 4L, 5L, 1L, 2L, 1L, 1L, 1L, 1L, 1L, 2L, 66L, 3L, 3L, 1L, 1L, 1L, 1L, 3L, 1L, 1L, 2L, 5L], ic: 202L, keys: [{"#t": "ae2:i", id: "minecraft:powered_rail"}, {"#t": "ae2:i", id: "minecraft:ender_pearl"}, {"#t": "ae2:i", id: "minecraft:diamond_axe", tag: {Damage: 0}}, {"#t": "ae2:i", id: "minecraft:gold_ingot"}, {"#t": "ae2:i", id: "minecraft:diamond_pickaxe", tag: {Damage: 0}}, {"#t": "ae2:i", id: "minecraft:glowstone_dust"}, {"#t": "ae2:i", id: "minecraft:blaze_powder"}, {"#t": "ae2:i", id: "minecraft:gunpowder"}, {"#t": "ae2:i", id: "minecraft:copper_ingot"}, {"#t": "ae2:i", id: "minecraft:red_dye"}, {"#t": "ae2:i", id: "minecraft:iron_boots", tag: {Damage: 0}}, {"#t": "ae2:i", id: "minecraft:emerald"}, {"#t": "ae2:i", id: "ae2:fluix_crystal"}, {"#t": "ae2:i", id: "minecraft:sugar"}, {"#t": "ae2:i", id: "minecraft:magma_cream"}, {"#t": "ae2:i", id: "minecraft:iron_helmet", tag: {Damage: 0}}, {"#t": "ae2:i", id: "minecraft:cooked_beef"}, {"#t": "ae2:i", id: "minecraft:glow_berries"}, {"#t": "ae2:i", id: "minecraft:blaze_rod"}, {"#t": "ae2:i", id: "minecraft:diamond"}, {"#t": "ae2:i", id: "minecraft:prismarine_crystals"}, {"#t": "ae2:i", id: "minecraft:blue_dye"}, {"#t": "ae2:i", id: "minecraft:iron_sword", tag: {Damage: 0}}, {"#t": "ae2:i", id: "minecraft:iron_pickaxe", tag: {Damage: 0}}, {"#t": "ae2:i", id: "minecraft:green_dye"}, {"#t": "ae2:i", id: "ae2:annihilation_plane"}, {"#t": "ae2:i", id: "minecraft:bread"}, {"#t": "ae2:i", id: "minecraft:rail"}, {"#t": "ae2:i", id: "minecraft:amethyst_shard"}, {"#t": "ae2:i", id: "minecraft:white_dye"}, {"#t": "ae2:i", id: "minecraft:diamond_shovel", tag: {Damage: 0}}, {"#t": "ae2:i", id: "minecraft:iron_leggings", tag: {Damage: 0}}, {"#t": "ae2:i", id: "minecraft:orange_dye"}, {"#t": "ae2:i", id: "minecraft:iron_chestplate", tag: {Damage: 0}}, {"#t": "ae2:i", id: "minecraft:potato"}, {"#t": "ae2:i", id: "minecraft:quartz"}, {"#t": "ae2:i", id: "minecraft:light_gray_dye"}, {"#t": "ae2:i", id: "minecraft:sweet_berries"}, {"#t": "ae2:i", id: "minecraft:apple"}]}}, item2: {Count: 1b, id: "ae2:item_storage_cell_16k", tag: {}}, item3: {Count: 1b, id: "ae2:item_storage_cell_16k", tag: {}}, item4: {Count: 1b, id: "ae2:item_storage_cell_16k", tag: {}}, item5: {Count: 1b, id: "ae2:item_storage_cell_16k", tag: {}}, item6: {Count: 1b, id: "ae2:item_storage_cell_16k", tag: {}}, item7: {Count: 1b, id: "ae2:item_storage_cell_16k", tag: {}}, item8: {Count: 1b, id: "ae2:item_storage_cell_16k", tag: {}}, item9: {Count: 1b, id: "ae2:item_storage_cell_16k", tag: {}}}, priority: 0, proxy: {p: 0}, visual: {cell0: {id: "ae2:item_storage_cell_16k", state: "types_full"}, cell1: {id: "ae2:item_storage_cell_16k", state: "not_empty"}, cell2: {id: "ae2:item_storage_cell_16k", state: "empty"}, cell3: {id: "ae2:item_storage_cell_16k", state: "empty"}, cell4: {id: "ae2:item_storage_cell_16k", state: "empty"}, cell5: {id: "ae2:item_storage_cell_16k", state: "empty"}, cell6: {id: "ae2:item_storage_cell_16k", state: "empty"}, cell7: {id: "ae2:item_storage_cell_16k", state: "empty"}, cell8: {id: "ae2:item_storage_cell_16k", state: "empty"}, cell9: {id: "ae2:item_storage_cell_16k", state: "empty"}, online: 1b}}},
        {pos: [11, 0, 7], state: "ae2:cell_workbench{facing:east,spin:0}", nbt: {copy_mode: "CLEAR_ON_REMOVE", id: "ae2:cell_workbench", visual: {}}},
        {pos: [11, 0, 8], state: "ae2:io_port{facing:south,powered:true,spin:0}", nbt: {fullness_mode: "EMPTY", id: "ae2:io_port", inv: {item0: {}, item1: {}, item10: {}, item11: {}, item2: {}, item3: {}, item4: {}, item5: {}, item6: {}, item7: {}, item8: {}, item9: {}}, lastRedstoneState: 1, operation_mode: "EMPTY", proxy: {p: 2}, redstone_controlled: "IGNORE", visual: {}}},
        {pos: [12, 0, 1], state: "minecraft:oak_wall_sign{facing:east,waterlogged:false}", nbt: {back_text: {color: "black", has_glowing_text: 0b, messages: ['""', '""', '""', '""']}, front_text: {color: "black", has_glowing_text: 0b, messages: ['"Some Dawer-like"', '"Thing"', '""', '""']}, id: "minecraft:sign", is_waxed: 0b}},
        {pos: [13, 0, 13], state: "minecraft:stone_brick_wall{east:none,north:none,south:none,up:true,waterlogged:false,west:none}"},
        {pos: [13, 0, 15], state: "minecraft:stone_brick_wall{east:none,north:none,south:none,up:true,waterlogged:false,west:none}"},
        {pos: [14, 0, 9], state: "ae2:condenser", nbt: {condenser_output: "TRASH", id: "ae2:condenser", inv: {item0: {}, item1: {}, item2: {}}, storedPower: 0.0d, visual: {}}},
        {pos: [14, 0, 11], state: "ae2:drive{facing:east,spin:0}", nbt: {id: "ae2:drive", inv: {item0: {Count: 1b, id: "ae2:item_storage_cell_16k", tag: {amts: [L; 2L, 65L], ic: 67L, keys: [{"#t": "ae2:i", id: "minecraft:arrow"}, {"#t": "ae2:i", id: "minecraft:bone"}], list: [{"#": 0L, "#t": "ae2:i", id: "minecraft:bone"}, {"#": 0L, "#t": "ae2:i", id: "minecraft:rotten_flesh"}, {"#": 0L, "#t": "ae2:i", id: "minecraft:carrot"}, {"#": 0L, "#t": "ae2:i", id: "minecraft:iron_ingot"}, {"#": 0L, "#t": "ae2:i", id: "minecraft:arrow"}], upgrades: [{Count: 1b, Slot: 0, id: "ae2:equal_distribution_card"}, {Count: 1b, Slot: 1, id: "ae2:void_card"}]}}, item1: {Count: 1b, id: "ae2:item_storage_cell_16k", tag: {amts: [L; 2L], ic: 2L, keys: [{"#t": "ae2:i", id: "minecraft:arrow"}], list: [{"#": 0L, "#t": "ae2:i", id: "minecraft:bone"}, {"#": 0L, "#t": "ae2:i", id: "minecraft:rotten_flesh"}, {"#": 0L, "#t": "ae2:i", id: "minecraft:carrot"}, {"#": 0L, "#t": "ae2:i", id: "minecraft:iron_ingot"}, {"#": 0L, "#t": "ae2:i", id: "minecraft:arrow"}], upgrades: [{Count: 1b, Slot: 0, id: "ae2:equal_distribution_card"}, {Count: 1b, Slot: 1, id: "ae2:void_card"}]}}, item2: {}, item3: {}, item4: {}, item5: {}, item6: {}, item7: {}, item8: {}, item9: {}}, priority: 0, proxy: {p: 0}, visual: {cell0: {id: "ae2:item_storage_cell_16k", state: "not_empty"}, cell1: {id: "ae2:item_storage_cell_16k", state: "not_empty"}, online: 1b}}},
        {pos: [14, 0, 12], state: "ae2:cable_bus{light_level:0,waterlogged:false}", nbt: {cable: {gn: {p: 0}, id: "ae2:orange_smart_cable", visual: {channelsNorth: 5, channelsSouth: 5, connections: ["north", "south"], missingChannel: 0b, powered: 1b}}, hasRedstone: 2, id: "ae2:cable_bus", visual: {}}},
        {pos: [14, 0, 13], state: "ae2:cable_bus{light_level:0,waterlogged:false}", nbt: {cable: {gn: {p: 0}, id: "ae2:orange_smart_cable", visual: {channelsNorth: 5, connections: ["north"], missingChannel: 0b, powered: 1b}}, hasRedstone: 2, id: "ae2:cable_bus", up: {fuzzy_mode: "IGNORE_ALL", gn: {p: 0}, id: "ae2:cable_interface", priority: 0, visual: {missingChannel: 0b, powered: 1b}}, visual: {}}},
        {pos: [15, 0, 13], state: "minecraft:stone_brick_wall{east:none,north:none,south:none,up:true,waterlogged:false,west:none}"},
        {pos: [15, 0, 15], state: "minecraft:stone_brick_wall{east:none,north:none,south:none,up:true,waterlogged:false,west:none}"},
        {pos: [7, 1, 13], state: "minecraft:melon"},
        {pos: [7, 1, 14], state: "minecraft:attached_melon_stem{facing:south}"},
        {pos: [7, 1, 15], state: "minecraft:melon"},
        {pos: [8, 1, 11], state: "ae2:cable_bus{light_level:0,waterlogged:false}", nbt: {cable: {gn: {p: 2}, id: "ae2:blue_smart_cable", visual: {channelsUp: 1, connections: ["up"], missingChannel: 0b, powered: 1b}}, hasRedstone: 2, id: "ae2:cable_bus", south: {access: "READ_WRITE", config: [{"#": 0L, "#t": "ae2:i", id: "minecraft:melon_slice"}], filter_on_extract: "YES", fuzzy_mode: "IGNORE_ALL", gn: {p: 2}, id: "ae2:storage_bus", priority: 1, storage_filter: "EXTRACTABLE_ONLY", visual: {missingChannel: 0b, powered: 1b}}, visual: {}}},
        {pos: [8, 1, 12], state: "minecraft:barrel{facing:west,open:false}", nbt: {Items: [{Count: 64b, Slot: 0b, id: "minecraft:melon_slice"}, {Count: 64b, Slot: 1b, id: "minecraft:melon_slice"}, {Count: 64b, Slot: 2b, id: "minecraft:melon_slice"}, {Count: 64b, Slot: 3b, id: "minecraft:melon_slice"}, {Count: 64b, Slot: 4b, id: "minecraft:melon_slice"}, {Count: 64b, Slot: 5b, id: "minecraft:melon_slice"}, {Count: 64b, Slot: 6b, id: "minecraft:melon_slice"}, {Count: 64b, Slot: 7b, id: "minecraft:melon_slice"}, {Count: 64b, Slot: 8b, id: "minecraft:melon_slice"}, {Count: 64b, Slot: 9b, id: "minecraft:melon_slice"}, {Count: 64b, Slot: 10b, id: "minecraft:melon_slice"}, {Count: 64b, Slot: 11b, id: "minecraft:melon_slice"}, {Count: 64b, Slot: 12b, id: "minecraft:melon_slice"}, {Count: 64b, Slot: 13b, id: "minecraft:melon_slice"}, {Count: 64b, Slot: 14b, id: "minecraft:melon_slice"}, {Count: 64b, Slot: 15b, id: "minecraft:melon_slice"}, {Count: 64b, Slot: 16b, id: "minecraft:melon_slice"}, {Count: 64b, Slot: 17b, id: "minecraft:melon_slice"}, {Count: 64b, Slot: 18b, id: "minecraft:melon_slice"}, {Count: 64b, Slot: 19b, id: "minecraft:melon_slice"}, {Count: 64b, Slot: 20b, id: "minecraft:melon_slice"}, {Count: 64b, Slot: 21b, id: "minecraft:melon_slice"}, {Count: 64b, Slot: 22b, id: "minecraft:melon_slice"}, {Count: 64b, Slot: 23b, id: "minecraft:melon_slice"}, {Count: 64b, Slot: 24b, id: "minecraft:melon_slice"}, {Count: 64b, Slot: 25b, id: "minecraft:melon_slice"}, {Count: 64b, Slot: 26b, id: "minecraft:melon_slice"}], id: "minecraft:barrel"}},
        {pos: [8, 1, 13], state: "minecraft:attached_melon_stem{facing:west}"},
        {pos: [8, 1, 14], state: "ae2:growth_accelerator{facing:up,powered:true}", nbt: {id: "ae2:growth_accelerator", proxy: {p: 2}, visual: {}}},
        {pos: [8, 1, 15], state: "minecraft:attached_melon_stem{facing:east}"},
        {pos: [9, 1, 13], state: "minecraft:melon"},
        {pos: [9, 1, 14], state: "minecraft:attached_melon_stem{facing:north}"},
        {pos: [9, 1, 15], state: "minecraft:melon"},
        {pos: [11, 1, 1], state: "ae2:cable_bus{light_level:0,waterlogged:false}", nbt: {cable: {gn: {p: 2}, id: "ae2:blue_smart_cable", visual: {channelsUp: 1, connections: ["up"], missingChannel: 0b, powered: 1b}}, down: {access: "READ_WRITE", config: [{"#": 0L, "#t": "ae2:i", id: "minecraft:coal"}], filter_on_extract: "YES", fuzzy_mode: "IGNORE_ALL", gn: {p: 2}, id: "ae2:storage_bus", priority: 1, storage_filter: "EXTRACTABLE_ONLY", visual: {missingChannel: 0b, powered: 1b}}, hasRedstone: 2, id: "ae2:cable_bus", visual: {}}},
        {pos: [11, 1, 3], state: "ae2:cable_bus{light_level:0,waterlogged:false}", nbt: {cable: {gn: {p: 2}, id: "ae2:blue_smart_cable", visual: {channelsDown: 1, channelsUp: 1, connections: ["down", "up"], missingChannel: 0b, powered: 1b}}, hasRedstone: 2, id: "ae2:cable_bus", visual: {}}},
        {pos: [11, 1, 5], state: "ae2:cable_bus{light_level:0,waterlogged:false}", nbt: {cable: {gn: {p: 2}, id: "ae2:blue_smart_cable", visual: {channelsDown: 1, channelsUp: 1, connections: ["down", "up"], missingChannel: 0b, powered: 1b}}, hasRedstone: 2, id: "ae2:cable_bus", visual: {}}},
        {pos: [11, 1, 7], state: "ae2:cable_bus{light_level:9,waterlogged:false}", nbt: {cable: {gn: {p: 2}, id: "ae2:blue_smart_cable", visual: {channelsSouth: 1, channelsUp: 2, connections: ["up", "south"], missingChannel: 0b, powered: 1b}}, east: {filter_type: "ALL", gn: {p: 2}, id: "ae2:crafting_terminal", sort_by: "NAME", sort_direction: "ASCENDING", spin: 0b, view_mode: "ALL", visual: {missingChannel: 0b, powered: 1b}}, hasRedstone: 2, id: "ae2:cable_bus", visual: {}}},
        {pos: [11, 1, 8], state: "ae2:cable_bus{light_level:0,waterlogged:false}", nbt: {cable: {gn: {p: 2}, id: "ae2:blue_smart_cable", visual: {channelsDown: 1, channelsNorth: 1, connections: ["down", "north"], missingChannel: 0b, powered: 1b}}, hasRedstone: 2, id: "ae2:cable_bus", up: {id: "ae2:cable_anchor", visual: {}}, visual: {}}},
        {pos: [13, 1, 10], state: "ae2:cable_bus{light_level:0,waterlogged:false}", nbt: {cable: {gn: {p: 0}, id: "ae2:orange_smart_cable", visual: {channelsEast: 5, connections: ["east"], missingChannel: 0b, powered: 1b}}, hasRedstone: 2, id: "ae2:cable_bus", up: {gn: {p: 0}, id: "ae2:quartz_fiber", outer: {p: 0}, visual: {missingChannel: 0b, powered: 1b}}, visual: {}}},
        {pos: [13, 1, 13], state: "minecraft:stone_bricks"},
        {pos: [13, 1, 14], state: "minecraft:stone_bricks"},
        {pos: [13, 1, 15], state: "minecraft:stone_bricks"},
        {pos: [14, 1, 9], state: "ae2:cable_bus{light_level:0,waterlogged:false}", nbt: {cable: {gn: {p: 0}, id: "ae2:orange_smart_cable", visual: {channelsSouth: 5, connections: ["south"], missingChannel: 0b, powered: 1b}}, down: {access: "READ_WRITE", filter_on_extract: "YES", fuzzy_mode: "IGNORE_ALL", gn: {p: 0}, id: "ae2:storage_bus", priority: -1, storage_filter: "EXTRACTABLE_ONLY", visual: {missingChannel: 0b, powered: 1b}}, hasRedstone: 2, id: "ae2:cable_bus", visual: {}}},
        {pos: [14, 1, 10], state: "ae2:interface", nbt: {fuzzy_mode: "IGNORE_ALL", id: "ae2:interface", priority: 0, proxy: {p: 0}, visual: {}}},
        {pos: [14, 1, 11], state: "ae2:cable_bus{light_level:9,waterlogged:false}", nbt: {cable: {gn: {p: 0}, id: "ae2:orange_smart_cable", visual: {channelsDown: 5, channelsNorth: 5, connections: ["down", "north"], missingChannel: 0b, powered: 1b}}, east: {filter_type: "ALL", gn: {p: 0}, id: "ae2:crafting_terminal", sort_by: "NAME", sort_direction: "ASCENDING", spin: 0b, view_mode: "ALL", visual: {missingChannel: 0b, powered: 1b}}, hasRedstone: 2, id: "ae2:cable_bus", visual: {}}},
        {pos: [14, 1, 13], state: "minecraft:hopper{enabled:true,facing:down}", nbt: {Items: [], TransferCooldown: 0, id: "minecraft:hopper"}},
        {pos: [14, 1, 14], state: "minecraft:stone_bricks"},
        {pos: [14, 1, 15], state: "minecraft:stone_bricks"},
        {pos: [15, 1, 13], state: "minecraft:stone_bricks"},
        {pos: [15, 1, 14], state: "minecraft:stone_bricks"},
        {pos: [15, 1, 15], state: "minecraft:stone_bricks"},
        {pos: [7, 2, 13], state: "ae2:cable_bus{light_level:0,waterlogged:false}", nbt: {cable: {gn: {p: 2}, id: "ae2:orange_smart_cable", visual: {channelsEast: 5, connections: ["east"], missingChannel: 0b, powered: 1b}}, down: {gn: {p: 2}, id: "ae2:annihilation_plane", visual: {missingChannel: 0b, powered: 1b}}, hasRedstone: 2, id: "ae2:cable_bus", visual: {}}},
        {pos: [7, 2, 15], state: "ae2:cable_bus{light_level:0,waterlogged:false}", nbt: {cable: {gn: {p: 2}, id: "ae2:orange_smart_cable", visual: {channelsEast: 5, connections: ["east"], missingChannel: 0b, powered: 1b}}, down: {gn: {p: 2}, id: "ae2:annihilation_plane", visual: {missingChannel: 0b, powered: 1b}}, hasRedstone: 2, id: "ae2:cable_bus", visual: {}}},
        {pos: [8, 2, 10], state: "ae2:cable_bus{light_level:0,waterlogged:false}", nbt: {cable: {gn: {p: 0}, id: "ae2:blue_smart_cable", visual: {channelsEast: 1, channelsSouth: 1, connections: ["south", "east"], missingChannel: 0b, powered: 1b}}, hasRedstone: 2, id: "ae2:cable_bus", visual: {}}},
        {pos: [8, 2, 11], state: "ae2:cable_bus{light_level:0,waterlogged:false}", nbt: {cable: {gn: {p: 2}, id: "ae2:blue_smart_cable", visual: {channelsDown: 1, channelsNorth: 1, connections: ["down", "north"], missingChannel: 0b, powered: 1b}}, hasRedstone: 2, id: "ae2:cable_bus", south: {gn: {p: 2}, id: "ae2:quartz_fiber", outer: {p: 2}, visual: {missingChannel: 0b, powered: 1b}}, visual: {}}},
        {pos: [8, 2, 12], state: "ae2:cable_bus{light_level:0,waterlogged:false}", nbt: {cable: {gn: {p: 2}, id: "ae2:orange_smart_cable", visual: {channelsNorth: 5, channelsSouth: 5, connections: ["north", "south"], missingChannel: 0b, powered: 1b}}, down: {access: "READ_WRITE", filter_on_extract: "YES", fuzzy_mode: "IGNORE_ALL", gn: {p: 2}, id: "ae2:storage_bus", priority: 0, storage_filter: "EXTRACTABLE_ONLY", visual: {missingChannel: 0b, powered: 1b}}, hasRedstone: 2, id: "ae2:cable_bus", visual: {}}},
        {pos: [8, 2, 13], state: "ae2:cable_bus{light_level:0,waterlogged:false}", nbt: {cable: {gn: {p: 2}, id: "ae2:orange_smart_cable", visual: {channelsEast: 5, channelsNorth: 5, channelsSouth: 5, channelsWest: 5, connections: ["north", "south", "west", "east"], missingChannel: 0b, powered: 1b}}, hasRedstone: 2, id: "ae2:cable_bus", visual: {}}},
        {pos: [8, 2, 14], state: "ae2:cable_bus{light_level:0,waterlogged:false}", nbt: {cable: {gn: {p: 2}, id: "ae2:orange_smart_cable", visual: {channelsDown: 5, channelsNorth: 5, channelsSouth: 5, connections: ["down", "north", "south"], missingChannel: 0b, powered: 1b}}, hasRedstone: 2, id: "ae2:cable_bus", visual: {}}},
        {pos: [8, 2, 15], state: "ae2:cable_bus{light_level:0,waterlogged:false}", nbt: {cable: {gn: {p: 2}, id: "ae2:orange_smart_cable", visual: {channelsEast: 5, channelsNorth: 5, channelsWest: 5, connections: ["north", "west", "east"], missingChannel: 0b, powered: 1b}}, hasRedstone: 2, id: "ae2:cable_bus", visual: {}}},
        {pos: [9, 2, 10], state: "ae2:cable_bus{light_level:0,waterlogged:false}", nbt: {cable: {gn: {p: 0}, id: "ae2:blue_smart_cable", visual: {channelsEast: 1, channelsWest: 1, connections: ["west", "east"], missingChannel: 0b, powered: 1b}}, hasRedstone: 2, id: "ae2:cable_bus", visual: {}}},
        {pos: [9, 2, 13], state: "ae2:cable_bus{light_level:0,waterlogged:false}", nbt: {cable: {gn: {p: 2}, id: "ae2:orange_smart_cable", visual: {channelsWest: 5, connections: ["west"], missingChannel: 0b, powered: 1b}}, down: {gn: {p: 2}, id: "ae2:annihilation_plane", visual: {missingChannel: 0b, powered: 1b}}, hasRedstone: 2, id: "ae2:cable_bus", visual: {}}},
        {pos: [9, 2, 15], state: "ae2:cable_bus{light_level:0,waterlogged:false}", nbt: {cable: {gn: {p: 2}, id: "ae2:orange_smart_cable", visual: {channelsWest: 5, connections: ["west"], missingChannel: 0b, powered: 1b}}, down: {gn: {p: 2}, id: "ae2:annihilation_plane", visual: {missingChannel: 0b, powered: 1b}}, hasRedstone: 2, id: "ae2:cable_bus", visual: {}}},
        {pos: [10, 2, 10], state: "ae2:cable_bus{light_level:0,waterlogged:false}", nbt: {cable: {gn: {p: 0}, id: "ae2:blue_smart_cable", visual: {channelsEast: 1, channelsWest: 1, connections: ["west", "east"], missingChannel: 0b, powered: 1b}}, hasRedstone: 2, id: "ae2:cable_bus", visual: {}}},
        {pos: [11, 2, 1], state: "ae2:cable_bus{light_level:0,waterlogged:false}", nbt: {cable: {gn: {p: 2}, id: "ae2:blue_smart_cable", visual: {channelsDown: 1, channelsSouth: 1, connections: ["down", "south"], missingChannel: 0b, powered: 1b}}, hasRedstone: 2, id: "ae2:cable_bus", visual: {}}},
        {pos: [11, 2, 2], state: "ae2:cable_bus{light_level:0,waterlogged:false}", nbt: {cable: {gn: {p: 2}, id: "ae2:blue_smart_cable", visual: {channelsNorth: 1, channelsSouth: 1, connections: ["north", "south"], missingChannel: 0b, powered: 1b}}, hasRedstone: 2, id: "ae2:cable_bus", visual: {}}},
        {pos: [11, 2, 3], state: "ae2:cable_bus{light_level:0,waterlogged:false}", nbt: {cable: {gn: {p: 2}, id: "ae2:blue_smart_dense_cable", visual: {channelsDown: 1, channelsNorth: 1, channelsSouth: 2, connections: ["down", "north", "south"], missingChannel: 0b, powered: 1b}}, hasRedstone: 2, id: "ae2:cable_bus", visual: {}}},
        {pos: [11, 2, 4], state: "ae2:cable_bus{light_level:0,waterlogged:false}", nbt: {cable: {gn: {p: 2}, id: "ae2:blue_smart_dense_cable", visual: {channelsNorth: 2, channelsSouth: 2, connections: ["north", "south"], missingChannel: 0b, powered: 1b}}, hasRedstone: 2, id: "ae2:cable_bus", visual: {}}},
        {pos: [11, 2, 5], state: "ae2:cable_bus{light_level:0,waterlogged:false}", nbt: {cable: {gn: {p: 2}, id: "ae2:blue_smart_dense_cable", visual: {channelsDown: 1, channelsNorth: 2, channelsSouth: 3, connections: ["down", "north", "south"], missingChannel: 0b, powered: 1b}}, hasRedstone: 2, id: "ae2:cable_bus", visual: {}}},
        {pos: [11, 2, 6], state: "ae2:cable_bus{light_level:0,waterlogged:false}", nbt: {cable: {gn: {p: 2}, id: "ae2:blue_smart_dense_cable", visual: {channelsNorth: 3, channelsSouth: 3, connections: ["north", "south"], missingChannel: 0b, powered: 1b}}, hasRedstone: 2, id: "ae2:cable_bus", visual: {}}},
        {pos: [11, 2, 7], state: "ae2:controller{state:online,type:block}", nbt: {id: "ae2:controller", internalCurrentPower: 0.0d, proxy: {p: 2}, visual: {}}},
        {pos: [11, 2, 8], state: "ae2:cable_bus{light_level:0,waterlogged:false}", nbt: {cable: {gn: {p: 0}, id: "ae2:blue_smart_dense_cable", visual: {channelsNorth: 2, channelsSouth: 2, connections: ["north", "south"], missingChannel: 0b, powered: 1b}}, down: {id: "ae2:cable_anchor", visual: {}}, hasRedstone: 2, id: "ae2:cable_bus", visual: {}}},
        {pos: [11, 2, 9], state: "ae2:cable_bus{light_level:0,waterlogged:false}", nbt: {cable: {gn: {p: 0}, id: "ae2:blue_smart_dense_cable", visual: {channelsNorth: 2, channelsSouth: 2, connections: ["north", "south"], missingChannel: 0b, powered: 1b}}, hasRedstone: 2, id: "ae2:cable_bus", visual: {}}},
        {pos: [11, 2, 10], state: "ae2:cable_bus{light_level:0,waterlogged:false}", nbt: {cable: {gn: {p: 0}, id: "ae2:blue_smart_dense_cable", visual: {channelsEast: 1, channelsNorth: 2, channelsWest: 1, connections: ["north", "west", "east"], missingChannel: 0b, powered: 1b}}, hasRedstone: 2, id: "ae2:cable_bus", visual: {}}},
        {pos: [12, 2, 10], state: "ae2:cable_bus{light_level:0,waterlogged:false}", nbt: {cable: {gn: {p: 0}, id: "ae2:blue_smart_cable", visual: {channelsEast: 1, channelsWest: 1, connections: ["west", "east"], missingChannel: 0b, powered: 1b}}, hasRedstone: 2, id: "ae2:cable_bus", visual: {}}},
        {pos: [13, 2, 10], state: "ae2:cable_bus{light_level:0,waterlogged:false}", nbt: {cable: {gn: {p: 0}, id: "ae2:blue_smart_cable", visual: {channelsDown: 0, channelsEast: 1, channelsWest: 1, connections: ["down", "west", "east"], missingChannel: 0b, powered: 1b}}, hasRedstone: 2, id: "ae2:cable_bus", visual: {}}},
        {pos: [13, 2, 13], state: "minecraft:mossy_cobblestone"},
        {pos: [13, 2, 14], state: "minecraft:tinted_glass"},
        {pos: [13, 2, 15], state: "minecraft:mossy_cobblestone"},
        {pos: [14, 2, 10], state: "ae2:cable_bus{light_level:0,waterlogged:false}", nbt: {cable: {gn: {p: 0}, id: "ae2:blue_smart_cable", visual: {channelsWest: 1, connections: ["west"], missingChannel: 0b, powered: 1b}}, down: {access: "READ_WRITE", config: [{"#": 0L, "#t": "ae2:i", id: "minecraft:arrow"}, {"#": 0L, "#t": "ae2:i", id: "minecraft:rotten_flesh"}, {"#": 0L, "#t": "ae2:i", id: "minecraft:bone"}], filter_on_extract: "YES", fuzzy_mode: "IGNORE_ALL", gn: {p: 0}, id: "ae2:storage_bus", priority: 1, storage_filter: "EXTRACTABLE_ONLY", visual: {missingChannel: 0b, powered: 1b}}, hasRedstone: 2, id: "ae2:cable_bus", visual: {}}},
        {pos: [14, 2, 13], state: "minecraft:tinted_glass"},
        {pos: [14, 2, 15], state: "minecraft:tinted_glass"},
        {pos: [15, 2, 13], state: "minecraft:mossy_cobblestone"},
        {pos: [15, 2, 14], state: "minecraft:tinted_glass"},
        {pos: [15, 2, 15], state: "minecraft:mossy_cobblestone"},
        {pos: [13, 3, 13], state: "minecraft:stone_bricks"},
        {pos: [13, 3, 14], state: "minecraft:stone_bricks"},
        {pos: [13, 3, 15], state: "minecraft:stone_bricks"},
        {pos: [14, 3, 13], state: "minecraft:stone_bricks"},
        {pos: [14, 3, 14], state: "minecraft:tinted_glass"},
        {pos: [14, 3, 15], state: "minecraft:stone_bricks"},
        {pos: [15, 3, 13], state: "minecraft:stone_bricks"},
        {pos: [15, 3, 14], state: "minecraft:stone_bricks"},
        {pos: [15, 3, 15], state: "minecraft:stone_bricks"}
    ],
    entities: [],
    palette: [
        "minecraft:dirt",
        "minecraft:melon",
        "minecraft:stone_bricks",
        "minecraft:mossy_cobblestone",
        "minecraft:tinted_glass",
        "minecraft:farmland{moisture:7}",
        "minecraft:smooth_stone_slab{type:bottom,waterlogged:true}",
        "minecraft:stone_brick_wall{east:none,north:none,south:none,up:true,waterlogged:false,west:none}",
        "minecraft:attached_melon_stem{facing:south}",
        "minecraft:attached_melon_stem{facing:west}",
        "minecraft:attached_melon_stem{facing:east}",
        "minecraft:attached_melon_stem{facing:north}",
        "minecraft:barrel{facing:east,open:false}",
        "ae2:drive{facing:east,spin:0}",
        "ae2:cell_workbench{facing:east,spin:0}",
        "ae2:io_port{facing:south,powered:true,spin:0}",
        "minecraft:oak_wall_sign{facing:east,waterlogged:false}",
        "ae2:condenser",
        "ae2:cable_bus{light_level:0,waterlogged:false}",
        "minecraft:barrel{facing:west,open:false}",
        "ae2:growth_accelerator{facing:up,powered:true}",
        "ae2:cable_bus{light_level:9,waterlogged:false}",
        "ae2:interface",
        "minecraft:hopper{enabled:true,facing:down}",
        "ae2:controller{state:online,type:block}",
        "ae2:creative_energy_cell"
    ]
}